2017-09-15T10:29:02.531658+00:00 heroku[router]: at=info method=POST path="/callback" host=tranquil-sands-63057.herokuapp.com request_id=6547e2f5-8817-4660-bfd2-9416db62cfb9 fwd="203.104.146.154" dyno=web.1 connect=0ms service=2641ms status=500 bytes=456 protocol=https
2017-09-15T10:29:02.519650+00:00 app[web.1]:   File "/app/.heroku/python/lib/python3.6/site-packages/flask/app.py", line 1982, in wsgi_app
2017-09-15T10:29:02.519653+00:00 app[web.1]:     rv = self.handle_user_exception(e)
2017-09-15T10:29:02.519639+00:00 app[web.1]: [2017-09-15 10:29:02,486] ERROR in app: Exception on /callback [POST]
2017-09-15T10:29:02.519651+00:00 app[web.1]:     response = self.full_dispatch_request()
2017-09-15T10:29:02.519655+00:00 app[web.1]:   File "/app/.heroku/python/lib/python3.6/site-packages/flask/_compat.py", line 33, in reraise
2017-09-15T10:29:02.519652+00:00 app[web.1]:   File "/app/.heroku/python/lib/python3.6/site-packages/flask/app.py", line 1614, in full_dispatch_request
2017-09-15T10:29:02.519654+00:00 app[web.1]:     reraise(exc_type, exc_value, tb)
2017-09-15T10:29:02.519649+00:00 app[web.1]: Traceback (most recent call last):
2017-09-15T10:29:02.519657+00:00 app[web.1]:   File "/app/.heroku/python/lib/python3.6/site-packages/flask/app.py", line 1598, in dispatch_request
2017-09-15T10:29:02.519655+00:00 app[web.1]:     raise value
2017-09-15T10:29:02.519662+00:00 app[web.1]:   File "/app/.heroku/python/lib/python3.6/site-packages/linebot/api.py", line 94, in reply_message
2017-09-15T10:29:02.519656+00:00 app[web.1]:   File "/app/.heroku/python/lib/python3.6/site-packages/flask/app.py", line 1612, in full_dispatch_request
2017-09-15T10:29:02.519653+00:00 app[web.1]:   File "/app/.heroku/python/lib/python3.6/site-packages/flask/app.py", line 1517, in handle_user_exception
2017-09-15T10:29:02.519658+00:00 app[web.1]:     return self.view_functions[rule.endpoint](**req.view_args)
2017-09-15T10:29:02.519657+00:00 app[web.1]:     rv = self.dispatch_request()
2017-09-15T10:29:02.519659+00:00 app[web.1]:     handler.handle(body, signature)
2017-09-15T10:29:02.519665+00:00 app[web.1]:     raise LineBotApiError(response.status_code, error)
2017-09-15T10:29:02.519659+00:00 app[web.1]:   File "/app/app.py", line 37, in callback
2017-09-15T10:29:02.519664+00:00 app[web.1]:   File "/app/.heroku/python/lib/python3.6/site-packages/linebot/api.py", line 271, in __check_error
2017-09-15T10:29:02.519660+00:00 app[web.1]:     func(event)
2017-09-15T10:29:02.526063+00:00 app[web.1]: linebot.exceptions.LineBotApiError: <LineBotApiError [The request body has 1 error(s)]>
2017-09-15T10:29:02.519661+00:00 app[web.1]:   File "/app/app.py", line 89, in handle_messag
2017-09-15T10:29:02.519660+00:00 app[web.1]:   File "/app/.heroku/python/lib/python3.6/site-packages/linebot/webhook.py", line 227, in handle
2017-09-15T10:29:02.519663+00:00 app[web.1]:   File "/app/.heroku/python/lib/python3.6/site-packages/linebot/api.py", line 262, in _post
2017-09-15T10:29:02.519662+00:00 app[web.1]:     TextSendMessage(text=content))
2017-09-15T10:29:02.519663+00:00 app[web.1]:     '/v2/bot/message/reply', data=json.dumps(data), timeout=timeout
2017-09-15T10:29:02.519664+00:00 app[web.1]:     self.__check_error(response)
2017-09-15T10:29:08.460662+00:00 heroku[router]: at=info method=POST path="/callback" host=tranquil-sands-63057.herokuapp.com request_id=2b6befcb-abb8-42af-8b0e-d6f949d306ee fwd="203.104.146.154" dyno=web.1 connect=0ms service=368ms status=200 bytes=161 protocol=https
2017-09-15T10:29:13.821276+00:00 heroku[router]: at=info method=POST path="/callback" host=tranquil-sands-63057.herokuapp.com request_id=47624288-eed8-4bd6-95be-056cb64c38b8 fwd="203.104.146.154" dyno=web.1 connect=0ms service=794ms status=500 bytes=456 protocol=https
2017-09-15T10:29:13.820313+00:00 app[web.1]: [2017-09-15 10:29:13,806] ERROR in app: Exception on /callback [POST]
2017-09-15T10:29:13.820328+00:00 app[web.1]: Traceback (most recent call last):
2017-09-15T10:29:13.820329+00:00 app[web.1]:   File "/app/.heroku/python/lib/python3.6/site-packages/flask/app.py", line 1982, in wsgi_app
2017-09-15T10:29:13.820331+00:00 app[web.1]:     rv = self.handle_user_exception(e)
2017-09-15T10:29:13.820330+00:00 app[web.1]:     response = self.full_dispatch_request()
2017-09-15T10:29:13.820331+00:00 app[web.1]:   File "/app/.heroku/python/lib/python3.6/site-packages/flask/app.py", line 1614, in full_dispatch_request
2017-09-15T10:29:13.820337+00:00 app[web.1]:   File "/app/.heroku/python/lib/python3.6/site-packages/flask/app.py", line 1517, in handle_user_exception
2017-09-15T10:29:13.820338+00:00 app[web.1]:     reraise(exc_type, exc_value, tb)
2017-09-15T10:29:13.820338+00:00 app[web.1]:   File "/app/.heroku/python/lib/python3.6/site-packages/flask/_compat.py", line 33, in reraise
2017-09-15T10:29:13.820340+00:00 app[web.1]:   File "/app/.heroku/python/lib/python3.6/site-packages/flask/app.py", line 1612, in full_dispatch_request
2017-09-15T10:29:13.820339+00:00 app[web.1]:     raise value
2017-09-15T10:29:13.820341+00:00 app[web.1]:     rv = self.dispatch_request()
2017-09-15T10:29:13.820341+00:00 app[web.1]:   File "/app/.heroku/python/lib/python3.6/site-packages/flask/app.py", line 1598, in dispatch_request
2017-09-15T10:29:13.820343+00:00 app[web.1]:     return self.view_functions[rule.endpoint](**req.view_args)
2017-09-15T10:29:13.820343+00:00 app[web.1]:   File "/app/app.py", line 37, in callback
2017-09-15T10:29:13.820344+00:00 app[web.1]:     handler.handle(body, signature)
2017-09-15T10:29:13.820345+00:00 app[web.1]:   File "/app/.heroku/python/lib/python3.6/site-packages/linebot/webhook.py", line 227, in handle
2017-09-15T10:29:13.820345+00:00 app[web.1]:     func(event)
2017-09-15T10:29:13.820346+00:00 app[web.1]:   File "/app/app.py", line 89, in handle_messag
2017-09-15T10:29:13.820347+00:00 app[web.1]:     TextSendMessage(text=content))
2017-09-15T10:29:13.820347+00:00 app[web.1]:   File "/app/.heroku/python/lib/python3.6/site-packages/linebot/api.py", line 94, in reply_message
2017-09-15T10:29:13.820348+00:00 app[web.1]:     '/v2/bot/message/reply', data=json.dumps(data), timeout=timeout
2017-09-15T10:29:13.820349+00:00 app[web.1]:   File "/app/.heroku/python/lib/python3.6/site-packages/linebot/api.py", line 262, in _post
2017-09-15T10:29:13.820350+00:00 app[web.1]:     self.__check_error(response)
2017-09-15T10:29:13.820358+00:00 app[web.1]: linebot.exceptions.LineBotApiError: <LineBotApiError [The request body has 1 error(s)]>
2017-09-15T10:29:13.820350+00:00 app[web.1]:   File "/app/.heroku/python/lib/python3.6/site-packages/linebot/api.py", line 271, in __check_error
2017-09-15T10:29:13.820351+00:00 app[web.1]:     raise LineBotApiError(response.status_code, error)
2017-09-15T10:44:36.823825+00:00 heroku[web.1]: Restarting
2017-09-15T10:44:36.824403+00:00 heroku[web.1]: State changed from up to starting
2017-09-15T10:44:37.733710+00:00 heroku[web.1]: Stopping all processes with SIGTERM
2017-09-15T10:44:37.751743+00:00 app[web.1]: [2017-09-15 10:44:37 +0000] [9] [INFO] Worker exiting (pid: 9)
2017-09-15T10:44:37.764393+00:00 app[web.1]: [2017-09-15 10:44:37 +0000] [8] [INFO] Worker exiting (pid: 8)
2017-09-15T10:44:37.775938+00:00 app[web.1]: [2017-09-15 10:44:37 +0000] [4] [INFO] Handling signal: term
2017-09-15T10:44:37.877631+00:00 app[web.1]: [2017-09-15 10:44:37 +0000] [4] [INFO] Shutting down: Master
2017-09-15T10:44:38.034270+00:00 heroku[web.1]: Process exited with status 0
2017-09-15T10:44:41.467653+00:00 heroku[web.1]: Starting process with command `gunicorn app:app`
2017-09-15T10:44:44.259283+00:00 app[web.1]: [2017-09-15 10:44:44 +0000] [4] [INFO] Starting gunicorn 19.6.0
2017-09-15T10:44:44.260323+00:00 app[web.1]: [2017-09-15 10:44:44 +0000] [4] [INFO] Listening at: http://0.0.0.0:4771 (4)
2017-09-15T10:44:44.260481+00:00 app[web.1]: [2017-09-15 10:44:44 +0000] [4] [INFO] Using worker: sync
2017-09-15T10:44:44.265002+00:00 app[web.1]: [2017-09-15 10:44:44 +0000] [8] [INFO] Booting worker with pid: 8
2017-09-15T10:44:44.359091+00:00 app[web.1]: [2017-09-15 10:44:44 +0000] [10] [INFO] Booting worker with pid: 10
2017-09-15T10:44:45.227262+00:00 heroku[web.1]: State changed from starting to up
2017-09-15T10:45:13.282381+00:00 heroku[router]: at=info method=POST path="/callback" host=tranquil-sands-63057.herokuapp.com request_id=ce80e05d-11e6-4258-b65a-952047c1fc6e fwd="203.104.146.154" dyno=web.1 connect=1ms service=455ms status=200 bytes=161 protocol=https
2017-09-15T10:45:20.693292+00:00 heroku[router]: at=info method=POST path="/callback" host=tranquil-sands-63057.herokuapp.com request_id=d6fe9303-92cf-49f0-9d4b-2da819e65c8d fwd="203.104.146.154" dyno=web.1 connect=1ms service=630ms status=500 bytes=456 protocol=https
2017-09-15T10:45:20.693128+00:00 app[web.1]: [2017-09-15 10:45:20,691] ERROR in app: Exception on /callback [POST]
2017-09-15T10:45:20.693140+00:00 app[web.1]: Traceback (most recent call last):
2017-09-15T10:45:20.693145+00:00 app[web.1]:   File "/app/.heroku/python/lib/python3.6/site-packages/flask/app.py", line 1982, in wsgi_app
2017-09-15T10:45:20.693146+00:00 app[web.1]:     response = self.full_dispatch_request()
2017-09-15T10:45:20.693148+00:00 app[web.1]:   File "/app/.heroku/python/lib/python3.6/site-packages/flask/app.py", line 1614, in full_dispatch_request
2017-09-15T10:45:20.693149+00:00 app[web.1]:     rv = self.handle_user_exception(e)
2017-09-15T10:45:20.693149+00:00 app[web.1]:   File "/app/.heroku/python/lib/python3.6/site-packages/flask/app.py", line 1517, in handle_user_exception
2017-09-15T10:45:20.693150+00:00 app[web.1]:     reraise(exc_type, exc_value, tb)
2017-09-15T10:45:20.693151+00:00 app[web.1]:   File "/app/.heroku/python/lib/python3.6/site-packages/flask/_compat.py", line 33, in reraise
2017-09-15T10:45:20.693151+00:00 app[web.1]:     raise value
2017-09-15T10:45:20.693152+00:00 app[web.1]:   File "/app/.heroku/python/lib/python3.6/site-packages/flask/app.py", line 1612, in full_dispatch_request
2017-09-15T10:45:20.693153+00:00 app[web.1]:     rv = self.dispatch_request()
2017-09-15T10:45:20.693153+00:00 app[web.1]:   File "/app/.heroku/python/lib/python3.6/site-packages/flask/app.py", line 1598, in dispatch_request
2017-09-15T10:45:20.693155+00:00 app[web.1]:     return self.view_functions[rule.endpoint](**req.view_args)
2017-09-15T10:45:20.693155+00:00 app[web.1]:   File "/app/app.py", line 37, in callback
2017-09-15T10:45:20.693156+00:00 app[web.1]:     handler.handle(body, signature)
2017-09-15T10:45:20.693157+00:00 app[web.1]:   File "/app/.heroku/python/lib/python3.6/site-packages/linebot/webhook.py", line 227, in handle
2017-09-15T10:45:20.693157+00:00 app[web.1]:     func(event)
2017-09-15T10:45:20.693158+00:00 app[web.1]:   File "/app/app.py", line 89, in handle_messag
2017-09-15T10:45:20.693158+00:00 app[web.1]:     TextSendMessage(text=content))
2017-09-15T10:45:20.693159+00:00 app[web.1]:   File "/app/.heroku/python/lib/python3.6/site-packages/linebot/api.py", line 94, in reply_message
2017-09-15T10:45:20.693160+00:00 app[web.1]:     '/v2/bot/message/reply', data=json.dumps(data), timeout=timeout
2017-09-15T10:45:20.693160+00:00 app[web.1]:   File "/app/.heroku/python/lib/python3.6/site-packages/linebot/api.py", line 262, in _post
2017-09-15T10:45:20.693161+00:00 app[web.1]:     self.__check_error(response)
2017-09-15T10:45:20.693162+00:00 app[web.1]:   File "/app/.heroku/python/lib/python3.6/site-packages/linebot/api.py", line 271, in __check_error
2017-09-15T10:45:20.693162+00:00 app[web.1]:     raise LineBotApiError(response.status_code, error)
2017-09-15T10:45:20.693168+00:00 app[web.1]: linebot.exceptions.LineBotApiError: <LineBotApiError [The request body has 1 error(s)]>
